Workbook

Sheet START_HERE
B2: MASTER FIRM PANEL
B6: Purpose | C6: Consolidated transition-readiness workbook based on the supplied example, eight sector reports, and their supporting files.
B7: Coverage | C7: 82 firm-sector observations across 8 sectors. PI Industries occurs in two sectors; do not count observations as unique firms.
B8: Start here | C8: Use Master_Panel for the familiar 44 variables plus audit columns. Filter analysis_include = Yes for complete workbook-coded observations without a known report conflict.
B9: Read the scores carefully | C9: DQS_total is calculated only when all ten indicators are numeric. Report_DQS_total is separate and can exist when indicator-level evidence is missing. Report-only matrices are not independently verified.
B10: Important conflict | C10: Fertilisers report Table 15 says only four firms are fully coded; the supporting workbook contains eleven full scores and a different roster. Both versions are retained and conflicts are excluded from the default analysis set. This is not a final research dataset.
B11: Missing data | C11: Yellow cells = missing/not provided, never zero. Zero scores mean the supplied source assigned zero. No missing score, year, revenue, or regulatory status was invented.
B12: Regulatory scope | C12: CCTS_obligated is blank pending firm/unit-level final notification evidence. Original flags remain on Original_Master. Exposure to a sector or CBAM is not proof of legal obligation.
B13: Finance | C13: Monetary amounts are ₹ crore; ratios are fractions. ROA uses year-end assets. Building borrowing-cost proxies include non-interest charges and can exceed 100%; do not treat them as pure interest rates.
B14: Source hierarchy | C14: Source-workbook final indicator scores are retained; report totals are shown alongside. Contradictions trigger review, not an automatic choice of whichever value is larger or more complete.
B15: Useful sheets | C15: Sector_Summary, Evidence_Log, Report_Findings, Paper_Financials, Building_FY_Panel, Double_Coding, Reliability, Checks, Flags, Change_Log, Data_Dictionary, Source_Index.
B16: Audit trail | C16: Original_Master, Original_Support and Original_Flags preserve the example’s cached values. All carried values remain source claims; company reports have not been independently re-audited.
B17: Workbook use | C17: Blue text = transcribed input; black = calculated formula; yellow = missing. Filters and frozen headings are enabled. Formulas have cached results and recalculate in Excel.
... B21: New conflict | C21: Khaitan has the same total in report and workbook, but the quantification subscore differs (0 vs 2). It is now excluded from the default analysis set.

Sheet Master_Panel
A1: firm_name | B1: sector | C1: CCTS_obligated | D1: listed | E1: exchange | F1: ownership | G1: BRSR_filer | H1: I1 | I1: I2 | J1: I3 | K1: I4 | L1: I5 | M1: I6 | N1: I7 | O1: I8 | P1: I9 | Q1: I10 | R1: DQS_total | S1: DQS_100 | T1: sub_quantification | U1: sub_strategy | V1: sub_credibility | W1: reporting_FY | X1: coder_id | Y1: second_coder_score | Z1: agreed_score | AA1: CBAM_covered_product | AB1: export_intensity | AC1: EU_export | AD1: PAT_legacy_entity | AE1: revenue | AF1: total_assets | AG1: PAT | AH1: ROA | AI1: total_debt | AJ1: finance_cost | AK1: cost_of_debt_proxy | AL1: capex | AM1: size_band | AN1: source_document | AO1: reporting_year | AP1: page_or_section | AQ1: URL | AR1: date_accessed | AS1: observation_id | AT1: coding_status | AU1: report_DQS_total | AV1: report_source | AW1: report_page_or_section | AX1: score_conflict | AY1: analysis_include | AZ1: financial_data_status | BA1: duplicate_entity_note | BB1: indicators_available | BC1: DQS_difference_vs_report | BD1: review_note | BE1: company_source_link_status | BF1: reported_CBAM_exposure_flag | BG1: reported_CCTS_exposure | BH1: reported_CCTS_units | BI1: reported_DQS_indicators_coded | BJ1: reported_adjusted_PAT | BK1: reported_assurance | BL1: reported_book_value | BM1: reported_consolidated_PAT | BN1: reported_cost_of_debt_year_end | BO1: reported_export_band | BP1: reported_long_term_debt | BQ1: reported_market_cap | BR1: reported_net_debt | BS1: reported_net_margin | BT1: reported_planned_green_capex_band | BU1: value_chain_segment | BV1: document_review_status | BW1: reviewed_documents | BX1: remaining_missing_fields
A2: Tata Steel Ltd | B2: Steel | D2: 1 | E2: NSE or BSE | F2: listed private | G2: 1 | H2: 3 | I2: 2 | J2: 1 | K2: 2 | L2: 2 | M2: 1 | N2: 0 | O2: 1 | P2: 3 | Q2: 3 | R2: =IF(COUNT(H2:Q2)=10,SUM(H2:Q2),"") -> 18 | S2: =IF(ISNUMBER(R2),R2/30*100,"") -> 60 | T2: =IF(COUNT(H2:J2,L2)=4,SUM(H2:J2,L2),"") -> 8 | U2: =IF(COUNT(K2,M2:O2)=4,SUM(K2,M2:O2),"") -> 4 | V2: =IF(COUNT(P2:Q2)=2,SUM(P2:Q2),"") -> 6 | W2: FY2024-25 | X2: Coder A / B (reconciled) | Y2: 30 | Z2: =IF(ISNUMBER(R2),R2,"") -> 18 | AB2: 0.03325071 | AC2: 1 | AE2: 218543 | AF2: 275459 | AG2: 3174 | AH2: =IF(AND(ISNUMBER(AG2),ISNUMBER(AF2),AF2>0),AG2/AF2,"") -> 0.011522586 | AI2: 94801 | AJ2: 7341 | AM2: Large | AN2: Annual Report (BRSR embedded) | AO2: FY2025 | AP2: per indicator - see Evidence_Log | AS2: OBS-001 | AT2: Workbook final scores; two coders supplied | AU2: 18 | AV2: Steel_Sector_Report.pdf | AW2: PDF p.22; Table 19 | AX2: No | AY2: Yes | AZ2: Inherited source values; verify scope/year | BB2: =COUNT(H2:Q2) -> 10 | BC2: =IF(AND(ISNUMBER(R2),ISNUMBER(AU2)),R2-AU2,"") -> 0 | BF2: 1 | BN2: 0.077435892 | BV2: Reviewed supplied PDF/DOCX and related sources | BW2: Steel group/Steel_Sector_Report.pdf | Steel group/data/ANOVA OUTPUT.docx | Steel group/data/CONJOINT ANALYSIS.docx | Steel group/data/Cronbach Alpha Calculation.xlsx | Steel group/data/DQS- excel.xlsx | Steel group/data/MDS OUTPUT.docx | Steel group/data/RMSM Form Responses.xlsx | BX2: CCTS_obligated, CBAM_covered_product, PAT_legacy_entity, cost_of_debt_proxy, capex, URL, date_accessed; Official unit-level legal notices, exact exchange identity, access dates, and additional comparable annual capex/finance inputs are not supplied. No valid prior-year debt series was located for average-debt proxy.
A3: JSW Steel Ltd | B3: Steel | D3: 1 | E3: NSE or BSE | F3: listed private | G3: 1 | H3: 2 | I3: 2 | J3: 3 | K3: 2 | L3: 1 | M3: 1 | N3: 0 | O3: 1 | P3: 3 | Q3: 1 | R3: =IF(COUNT(H3:Q3)=10,SUM(H3:Q3),"") -> 16 | S3: =IF(ISNUMBER(R3),R3/30*100,"") -> 53.333333 | T3: =IF(COUNT(H3:J3,L3)=4,SUM(H3:J3,L3),"") -> 8 | U3: =IF(COUNT(K3,M3:O3)=4,SUM(K3,M3:O3),"") -> 4 | V3: =IF(COUNT(P3:Q3)=2,SUM(P3:Q3),"") -> 4 | W3: FY2025-26 | X3: Coder A / B (reconciled) | Y3: 16 | Z3: =IF(ISNUMBER(R3),R3,"") -> 16 | AB3: 0.047558404 | AC3: 1 | AE3: 168824 | AF3: 240445 | AG3: 3491 | AH3: =IF(AND(ISNUMBER(AG3),ISNUMBER(AF3),AF3>0),AG3/AF3,"") -> 0.014518913 | AI3: 98752 | AJ3: 8412 | AM3: Large | AN3: Business Responsibility and Sustainability Report (standalone filing) | AO3: FY2025 | AP3: per indicator - see Evidence_Log | AS3: OBS-002 | AT3: Workbook final scores; two coders supplied | AU3: 16 | AV3: Steel_Sector_Report.pdf | AW3: PDF p.22; Table 19 | AX3: No | AY3: Yes | AZ3: Inherited source values; verify scope/year | BB3: =COUNT(H3:Q3) -> 10 | BC3: =IF(AND(ISNUMBER(R3),ISNUMBER(AU3)),R3-AU3,"") -> 0 | BF3: 1 | BN3: 0.085183085 | BV3: Reviewed supplied PDF/DOCX and related sources | BW3: Steel group/Steel_Sector_Report.pdf | Steel group/data/ANOVA OUTPUT.docx | Steel group/data/CONJOINT ANALYSIS.docx | Steel group/data/Cronbach Alpha Calculation.xlsx | Steel group/data/DQS- excel.xlsx | Steel group/data/MDS OUTPUT.docx | Steel group/data/RMSM Form Responses.xlsx | BX3: CCTS_obligated, CBAM_covered_product, PAT_legacy_entity, cost_of_debt_proxy, capex, URL, date_accessed; Official unit-level legal notices, exact exchange identity, access dates, and additional comparable annual capex/finance inputs are not supplied. No valid prior-year debt series was located for average-debt proxy.
A4: Steel Authority of India (SAIL) | B4: Steel | D4: 1 | E4: NSE or BSE | F4: PSU | G4: 1 | H4: 2 | I4: 2 | J4: 2 | K4: 2 | L4: 1 | M4: 0 | N4: 0 | O4: 1 | P4: 3 | Q4: 3 | R4: =IF(COUNT(H4:Q4)=10,SUM(H4:Q4),"") -> 16 | S4: =IF(ISNUMBER(R4),R4/30*100,"") -> 53.333333 | T4: =IF(COUNT(H4:J4,L4)=4,SUM(H4:J4,L4),"") -> 7 | U4: =IF(COUNT(K4,M4:O4)=4,SUM(K4,M4:O4),"") -> 3 | V4: =IF(COUNT(P4:Q4)=2,SUM(P4:Q4),"") -> 6 | W4: FY2024-25 | X4: Coder A / B (reconciled) | Y4: 17 | Z4: =IF(ISNUMBER(R4),R4,"") -> 16 | AB4: 0.0048012764 | AC4: unknown | AE4: 102479 | AF4: 136718 | AG4: 2372 | AH4: =IF(AND(ISNUMBER(AG4),ISNUMBER(AF4),AF4>0),AG4/AF4,"") -> 0.017349581 | AI4: 36934 | AJ4: 2793 | AM4: Large | AN4: Business Responsibility and Sustainability Report (standalone filing) | AO4: FY2025 | AP4: per indicator - see Evidence_Log | AS4: OBS-003 | AT4: Workbook final scores; two coders supplied | AU4: 16 | AV4: Steel_Sector_Report.pdf | AW4: PDF p.22; Table 19 | AX4: No | AY4: Yes | AZ4: Inherited source values; verify scope/year | BB4: =COUNT(H4:Q4) -> 10 | BC4: =IF(AND(ISNUMBER(R4),ISNUMBER(AU4)),R4-AU4,"") -> 0 | BF4: 1 | BN4: 0.075621379 | BV4: Reviewed supplied PDF/DOCX and related sources | BW4: Steel group/Steel_Sector_Report.pdf | Steel group/data/ANOVA OUTPUT.docx | Steel group/data/CONJOINT ANALYSIS.docx | Steel group/data/Cronbach Alpha Calculation.xlsx | Steel group/data/DQS- excel.xlsx | Steel group/data/MDS OUTPUT.docx | Steel group/data/RMSM Form Responses.xlsx | BX4: CCTS_obligated, CBAM_covered_product, EU_export, PAT_legacy_entity, cost_of_debt_proxy, capex, URL, date_accessed; Official unit-level legal notices, exact exchange identity, access dates, and additional comparable annual capex/finance inputs are not supplied. No valid prior-year debt series was located for average-debt proxy.
A5: Jindal Steel Ltd (JSPL) | B5: Steel | D5: 1 | E5: NSE or BSE | F5: listed private | G5: 1 | H5: 2 | I5: 2 | J5: 3 | K5: 3 | L5: 1 | M5: 2 | N5: 0 | O5: 2 | P5: 3 | Q5: 1 | R5: =IF(COUNT(H5:Q5)=10,SUM(H5:Q5),"") -> 19 | S5: =IF(ISNUMBER(R5),R5/30*100,"") -> 63.333333 | T5: =IF(COUNT(H5:J5,L5)=4,SUM(H5:J5,L5),"") -> 8 | U5: =IF(COUNT(K5,M5:O5)=4,SUM(K5,M5:O5),"") -> 7 | V5: =IF(COUNT(P5:Q5)=2,SUM(P5:Q5),"") -> 4 | W5: FY2025-26 | X5: Coder A / B (reconciled) | Y5: 21 | Z5: =IF(ISNUMBER(R5),R5,"") -> 19 | AB5: 0.052451675 | AC5: unknown | AE5: 50129 | AF5: 85766 | AG5: 2846 | AH5: =IF(AND(ISNUMBER(AG5),ISNUMBER(AF5),AF5>0),AG5/AF5,"") -> 0.033183313 | AI5: 18406 | AJ5: 1312 | AM5: Large | AN5: Integrated Report (BRSR embedded) | AO5: FY2025 | AP5: per indicator - see Evidence_Log | AS5: OBS-004 | AT5: Workbook final scores; two coders supplied | AU5: 19 | AV5: Steel_Sector_Report.pdf | AW5: PDF p.22; Table 19 | AX5: No | AY5: Yes | AZ5: Inherited source values; verify scope/year | BB5: =COUNT(H5:Q5) -> 10 | BC5: =IF(AND(ISNUMBER(R5),ISNUMBER(AU5)),R5-AU5,"") -> 0 | BF5: 0 | BN5: 0.071281104 | BV5: Reviewed supplied PDF/DOCX and related sources | BW5: Steel group/Steel_Sector_Report.pdf | Steel group/data/ANOVA OUTPUT.docx | Steel group/data/CONJOINT ANALYSIS.docx | Steel group/data/Cronbach Alpha Calculation.xlsx | Steel group/data/DQS- excel.xlsx | Steel group/data/MDS OUTPUT.docx | Steel group/data/RMSM Form Responses.xlsx | BX5: CCTS_obligated, CBAM_covered_product, EU_export, PAT_legacy_entity, cost_of_debt_proxy, capex, URL, date_accessed; Official unit-level legal notices, exact exchange identity, access dates, and additional comparable annual capex/finance inputs are not supplied. No valid prior-year debt series was located for average-debt proxy.
A6: Jindal Stainless Ltd | B6: Steel | D6: 1 | E6: NSE or BSE | F6: listed private | G6: 1 | H6: 3 | I6: 2 | J6: 2 | K6: 2 | L6: 2 | M6: 0 | N6: 0 | O6: 1 | P6: 3 | Q6: 2 | R6: =IF(COUNT(H6:Q6)=10,SUM(H6:Q6),"") -> 17 | S6: =IF(ISNUMBER(R6),R6/30*100,"") -> 56.666667 | T6: =IF(COUNT(H6:J6,L6)=4,SUM(H6:J6,L6),"") -> 9 | U6: =IF(COUNT(K6,M6:O6)=4,SUM(K6,M6:O6),"") -> 3 | V6: =IF(COUNT(P6:Q6)=2,SUM(P6:Q6),"") -> 5 | W6: FY2024-25 | X6: Coder A / B (reconciled) | Y6: 17 | Z6: =IF(ISNUMBER(R6),R6,"") -> 17 | AB6: 0.14722451 | AC6: 1 | AE6: 39312 | AF6: 35917 | AG6: 2500 | AH6: =IF(AND(ISNUMBER(AG6),ISNUMBER(AF6),AF6>0),AG6/AF6,"") -> 0.069604922 | AI6: 6402 | AJ6: 612 | AM6: Large | AN6: Business Responsibility and Sustainability Report (standalone filing) | AO6: FY2025 | AP6: per indicator - see Evidence_Log | AS6: OBS-005 | AT6: Workbook final scores; two coders supplied | AU6: 17 | AV6: Steel_Sector_Report.pdf | AW6: PDF p.22; Table 19 | AX6: No | AY6: Yes | AZ6: Inherited source values; verify scope/year | BB6: =COUNT(H6:Q6) -> 10 | BC6: =IF(AND(ISNUMBER(R6),ISNUMBER(AU6)),R6-AU6,"") -> 0 | BF6: 1 | BN6: 0.095595127 | BV6: Reviewed supplied PDF/DOCX and related sources | BW6: Steel group/Steel_Sector_Report.pdf | Steel group/data/ANOVA OUTPUT.docx | Steel group/data/CONJOINT ANALYSIS.docx | Steel group/data/Cronbach Alpha Calculation.xlsx | Steel group/data/DQS- excel.xlsx | Steel group/data/MDS OUTPUT.docx | Steel group/data/RMSM Form Responses.xlsx | BX6: CCTS_obligated, CBAM_covered_product, PAT_legacy_entity, cost_of_debt_proxy, capex, URL, date_accessed; Official unit-level legal notices, exact exchange identity, access dates, and additional comparable annual capex/finance inputs are not supplied. No valid prior-year debt series was located for average-debt proxy.
A7: NMDC Steel Ltd | B7: Steel | D7: 1 | E7: NSE or BSE | F7: PSU | G7: 1 | H7: 3 | I7: 2 | J7: 1 | K7: 1 | L7: 1 | M7: 1 | N7: 0 | O7: 1 | P7: 3 | Q7: 1 | R7: =IF(COUNT(H7:Q7)=10,SUM(H7:Q7),"") -> 14 | S7: =IF(ISNUMBER(R7),R7/30*100,"") -> 46.666667 | T7: =IF(COUNT(H7:J7,L7)=4,SUM(H7:J7,L7),"") -> 7 | U7: =IF(COUNT(K7,M7:O7)=4,SUM(K7,M7:O7),"") -> 3 | V7: =IF(COUNT(P7:Q7)=2,SUM(P7:Q7),"") -> 4 | X7: Coder A / B (reconciled) | Y7: 14 | Z7: =IF(ISNUMBER(R7),R7,"") -> 14 | AB7: 0 | AC7: unknown | AE7: 8503 | AF7: 28470 | AG7: -2374 | AH7: =IF(AND(ISNUMBER(AG7),ISNUMBER(AF7),AF7>0),AG7/AF7,"") -> -0.08338602 | AI7: 5909 | AJ7: 652 | AM7: Mid | AN7: Annual Report, NMDC Limited (BRSR embedded) | AO7: FY2025 | AP7: per indicator - see Evidence_Log | AS7: OBS-006 | AT7: Workbook final scores; two coders supplied | AU7: 14 | AV7: Steel_Sector_Report.pdf | AW7: PDF p.22; Table 19 | AX7: No | AY7: Yes | AZ7: Inherited source values; verify scope/year | BB7: =COUNT(H7:Q7) -> 10 | BC7: =IF(AND(ISNUMBER(R7),ISNUMBER(AU7)),R7-AU7,"") -> 0 | BF7: 0 | BN7: 0.11034016 | BV7: Reviewed supplied PDF/DOCX and related sources | BW7: Steel group/Steel_Sector_Report.pdf | Steel group/data/ANOVA OUTPUT.docx | Steel group/data/CONJOINT ANALYSIS.docx | Steel group/data/Cronbach Alpha Calculation.xlsx | Steel group/data/DQS- excel.xlsx | Steel group/data/MDS OUTPUT.docx | Steel group/data/RMSM Form Responses.xlsx | BX7: CCTS_obligated, reporting_FY, CBAM_covered_product, EU_export, PAT_legacy_entity, cost_of_debt_proxy, capex, URL, date_accessed; Official unit-level legal notices, exact exchange identity, access dates, and additional comparable annual capex/finance inputs are not supplied. No valid prior-year debt series was located for average-debt proxy. NMDC Limited/NMDC Steel Ltd entity mismatch prevents copying miner disclosure/year/capex into steel row.
A8: Shyam Metalics & Energy Ltd | B8: Steel | D8: 1 | E8: NSE or BSE | F8: listed private | G8: 1 | H8: 2 | I8: 1 | J8: 0 | K8: 0 | L8: 0 | M8: 1 | N8: 0 | O8: 1 | P8: 0 | Q8: 1 | R8: =IF(COUNT(H8:Q8)=10,SUM(H8:Q8),"") -> 6 | S8: =IF(ISNUMBER(R8),R8/30*100,"") -> 20 | T8: =IF(COUNT(H8:J8,L8)=4,SUM(H8:J8,L8),"") -> 3 | U8: =IF(COUNT(K8,M8:O8)=4,SUM(K8,M8:O8),"") -> 2 | V8: =IF(COUNT(P8:Q8)=2,SUM(P8:Q8),"") -> 1 | W8: FY2024-25 | X8: Coder A / B (reconciled) | Y8: 6 | Z8: =IF(ISNUMBER(R8),R8,"") -> 6 | AB8: 0.0054868543 | AC8: unknown | AE8: 15138 | AF8: 16320 | AG8: 909 | AH8: =IF(AND(ISNUMBER(AG8),ISNUMBER(AF8),AF8>0),AG8/AF8,"") -> 0.055698529 | AI8: 789 | AJ8: 144 | AM8: Mid | AN8: Business Responsibility and Sustainability Report + Annual Report | AO8: FY2025 | AP8: per indicator - see Evidence_Log | AS8: OBS-007 | AT8: Workbook final scores; two coders supplied | AU8: 6 | AV8: Steel_Sector_Report.pdf | AW8: PDF p.22; Table 19 | AX8: No | AY8: Yes | AZ8: Inherited source values; verify scope/year | BB8: =COUNT(H8:Q8) -> 10 | BC8: =IF(AND(ISNUMBER(R8),ISNUMBER(AU8)),R8-AU8,"") -> 0 | BF8: 1 | BN8: 0.18250951 | BV8: Reviewed supplied PDF/DOCX and related sources | BW8: Steel group/Steel_Sector_Report.pdf | Steel group/data/ANOVA OUTPUT.docx | Steel group/data/CONJOINT ANALYSIS.docx | Steel group/data/Cronbach Alpha Calculation.xlsx | Steel group/data/DQS- excel.xlsx | Steel group/data/MDS OUTPUT.docx | Steel group/data/RMSM Form Responses.xlsx | BX8: CCTS_obligated, CBAM_covered_product, EU_export, PAT_legacy_entity, cost_of_debt_proxy, capex, URL, date_accessed; Official unit-level legal notices, exact exchange identity, access dates, and additional comparable annual capex/finance inputs are not supplied. No valid prior-year debt series was located for average-debt proxy.
A9: Godawari Power & Ispat Ltd | B9: Steel | D9: 1 | E9: NSE or BSE | F9: listed private | G9: 1 | H9: 3 | I9: 0 | J9: 0 | K9: 2 | L9: 2 | M9: 2 | N9: 0 | O9: 1 | P9: 1 | Q9: 2 | R9: =IF(COUNT(H9:Q9)=10,SUM(H9:Q9),"") -> 13 | S9: =IF(ISNUMBER(R9),R9/30*100,"") -> 43.333333 | T9: =IF(COUNT(H9:J9,L9)=4,SUM(H9:J9,L9),"") -> 5 | U9: =IF(COUNT(K9,M9:O9)=4,SUM(K9,M9:O9),"") -> 5 | V9: =IF(COUNT(P9:Q9)=2,SUM(P9:Q9),"") -> 3 | W9: FY2024-25 | X9: Coder A / B (reconciled) | Y9: 17 | Z9: =IF(ISNUMBER(R9),R9,"") -> 13 | AB9: 0.013298659 | AC9: unknown | AE9: 5375.73 | AF9: 6157 | AG9: 813 | AH9: =IF(AND(ISNUMBER(AG9),ISNUMBER(AF9),AF9>0),AG9/AF9,"") -> 0.13204483 | AI9: 309 | AJ9: 55.39 | AM9: Mid | AN9: Annual Report (BRSR embedded) | AO9: FY2025 | AP9: per indicator - see Evidence_Log | AS9: OBS-008 | AT9: Workbook final scores; two coders supplied | AU9: 13 | AV9: Steel_Sector_Report.pdf | AW9: PDF p.22; Table 19 | AX9: No | AY9: Yes | AZ9: Inherited source values; verify scope/year | BB9: =COUNT(H9:Q9) -> 10 | BC9: =IF(AND(ISNUMBER(R9),ISNUMBER(AU9)),R9-AU9,"") -> 0 | BF9: 0 | BN9: 0.17925566 | BV9: Reviewed supplied PDF/DOCX and related sources | BW9: Steel group/Steel_Sector_Report.pdf | Steel group/data/ANOVA OUTPUT.docx | Steel group/data/CONJOINT ANALYSIS.docx | Steel group/data/Cronbach Alpha Calculation.xlsx | Steel group/data/DQS- excel.xlsx | Steel group/data/MDS OUTPUT.docx | Steel group/data/RMSM Form Responses.xlsx | BX9: CCTS_obligated, CBAM_covered_product, EU_export, PAT_legacy_entity, cost_of_debt_proxy, capex, URL, date_accessed; Official unit-level legal notices, exact exchange identity, access dates, and additional comparable annual capex/finance inputs are not supplied. No valid prior-year debt series was located for average-debt proxy.
A10: Kalyani Steels Ltd | B10: Steel | D10: 1 | E10: NSE or BSE | F10: listed private | G10: 1 | H10: 2 | I10: 0 | J10: 0 | K10: 0 | L10: 0 | M10: 2 | N10: 0 | O10: 0 | P10: 0 | Q10: 1 | R10: =IF(COUNT(H10:Q10)=10,SUM(H10:Q10),"") -> 5 | S10: =IF(ISNUMBER(R10),R10/30*100,"") -> 16.666667 | T10: =IF(COUNT(H10:J10,L10)=4,SUM(H10:J10,L10),"") -> 2 | U10: =IF(COUNT(K10,M10:O10)=4,SUM(K10,M10:O10),"") -> 2 | V10: =IF(COUNT(P10:Q10)=2,SUM(P10:Q10),"") -> 1 | W10: FY2025-26 | X10: Coder A / B (reconciled) | Y10: 5 | Z10: =IF(ISNUMBER(R10),R10,"") -> 5 | AB10: 0.0070479314 | AC10: unknown | AD10: 1 | AE10: 1982 | AF10: 2732 | AG10: 256 | AH10: =IF(AND(ISNUMBER(AG10),ISNUMBER(AF10),AF10>0),AG10/AF10,"") -> 0.093704246 | AI10: 438 | AJ10: 19 | AM10: Mid | AN10: Annual Report (BRSR embedded) | AO10: FY2025 | AP10: per indicator - see Evidence_Log | AS10: OBS-009 | AT10: Workbook final scores; two coders supplied | AU10: 5 | AV10: Steel_Sector_Report.pdf | AW10: PDF p.22; Table 19 | AX10: No | AY10: Yes | AZ10: Inherited source values; verify scope/year | BB10: =COUNT(H10:Q10) -> 10 | BC10: =IF(AND(ISNUMBER(R10),ISNUMBER(AU10)),R10-AU10,"") -> 0 | BF10: 0 | BN10: 0.043378995 | BV10: Reviewed supplied PDF/DOCX and related sources | BW10: Steel group/Steel_Sector_Report.pdf | Steel group/data/ANOVA OUTPUT.docx | Steel group/data/CONJOINT ANALYSIS.docx | Steel group/data/Cronbach Alpha Calculation.xlsx | Steel group/data/DQS- excel.xlsx | Steel group/data/MDS OUTPUT.docx | Steel group/data/RMSM Form Responses.xlsx | BX10: CCTS_obligated, CBAM_covered_product, EU_export, cost_of_debt_proxy, capex, URL, date_accessed; Official unit-level legal notices, exact exchange identity, access dates, and additional comparable annual capex/finance inputs are not supplied. No valid prior-year debt series was located for average-debt proxy.
A11: Dalmia Bharat | B11: Cement | D11: 1 | G11: 1 | H11: 3 | I11: 3 | J11: 3 | K11: 3 | L11: 2 | M11: 2 | N11: 0 | O11: 2 | P11: 3 | Q11: 2 | R11: =IF(COUNT(H11:Q11)=10,SUM(H11:Q11),"") -> 23 | S11: =IF(ISNUMBER(R11),R11/30*100,"") -> 76.666667 | T11: =IF(COUNT(H11:J11,L11)=4,SUM(H11:J11,L11),"") -> 11 | U11: =IF(COUNT(K11,M11:O11)=4,SUM(K11,M11:O11),"") -> 7 | V11: =IF(COUNT(P11:Q11)=2,SUM(P11:Q11),"") -> 5 | W11: FY 2025-26 | AA11: 1 | AC11: unknown | AH11: =IF(AND(ISNUMBER(AG11),ISNUMBER(AF11),AF11>0),AG11/AF11,"") | AN11: Dalmia Bharat IR 2025-26; Dalmia Bharat IR 2025-26 (reviewed) | AP11: per indicator - see Evidence_Log | AS11: OBS-010 | AT11: Workbook coded; single coder | AU11: 23 | AV11: Cement_Report.pdf | AW11: PDF p.13; section 7.2 | AX11: No | AY11: Yes | AZ11: Not supplied | BB11: =COUNT(H11:Q11) -> 10 | BC11: =IF(AND(ISNUMBER(R11),ISNUMBER(AU11)),R11-AU11,"") -> 0 | BH11: 12 | BO11: <0.1% | BV11: Reviewed supplied PDF/DOCX and related sources | BW11: Cement/Annexure A.xlsx | Cement/Annexure B.docx | Cement/Annexure C.xlsx | Cement/Annexure D.xlsx | Cement/Annexure E.xlsx | Cement/Cement_Report.pdf | BX11: CCTS_obligated, exchange, ownership, coder_id, second_coder_score, agreed_score, export_intensity, EU_export, PAT_legacy_entity, revenue, total_assets, PAT, ROA, total_debt, finance_cost, cost_of_debt_proxy, capex, size_band, reporting_year, URL, date_accessed; No firm-level revenue/PAT/assets/debt/finance-cost table in supplied report or Word interviews. Survey and MDS values are respondent/perception data and cannot fill company financials. Single-coder identity and second coder are unrecorded. EU-specific exports not disclosed. Exact company-report URLs and access dates not supplied.
A12: Shree Cement | B12: Cement | D12: 1 | G12: 1 | H12: 3 | I12: 3 | J12: 3 | K12: 3 | L12: 2 | M12: 2 | N12: 0 | O12: 1 | P12: 3 | Q12: 2 | R12: =IF(COUNT(H12:Q12)=10,SUM(H12:Q12),"") -> 22 | S12: =IF(ISNUMBER(R12),R12/30*100,"") -> 73.333333 | T12: =IF(COUNT(H12:J12,L12)=4,SUM(H12:J12,L12),"") -> 11 | U12: =IF(COUNT(K12,M12:O12)=4,SUM(K12,M12:O12),"") -> 6 | V12: =IF(COUNT(P12:Q12)=2,SUM(P12:Q12),"") -> 5 | W12: FY 2025-26 | AA12: 1 | AB12: 0 | AC12: unknown | AH12: =IF(AND(ISNUMBER(AG12),ISNUMBER(AF12),AF12>0),AG12/AF12,"") | AN12: Shree Cement IR 2025-26; Shree Cement IR 2025-26 (reviewed) | AP12: per indicator - see Evidence_Log | AS12: OBS-011 | AT12: Workbook coded; single coder | AU12: 22 | AV12: Cement_Report.pdf | AW12: PDF p.13; section 7.2 | AX12: No | AY12: Yes | AZ12: Not supplied | BB12: =COUNT(H12:Q12) -> 10 | BC12: =IF(AND(ISNUMBER(R12),ISNUMBER(AU12)),R12-AU12,"") -> 0 | BH12: 7 | BV12: Reviewed supplied PDF/DOCX and related sources | BW12: Cement/Annexure A.xlsx | Cement/Annexure B.docx | Cement/Annexure C.xlsx | Cement/Annexure D.xlsx | Cement/Annexure E.xlsx | Cement/Cement_Report.pdf | BX12: CCTS_obligated, exchange, ownership, coder_id, second_coder_score, agreed_score, EU_export, PAT_legacy_entity, revenue, total_assets, PAT, ROA, total_debt, finance_cost, cost_of_debt_proxy, capex, size_band, reporting_year, URL, date_accessed; No firm-level revenue/PAT/assets/debt/finance-cost table in supplied report or Word interviews. Survey and MDS values are respondent/perception data and cannot fill company financials. Single-coder identity and second coder are unrecorded. EU-specific exports not disclosed. Exact company-report URLs and access dates not supplied.
A13: ACC Limited | B13: Cement | D13: 1 | G13: 1 | H13: 3 | I13: 2 | J13: 3 | K13: 3 | L13: 2 | M13: 2 | N13: 3 | O13: 3 | P13: 2 | Q13: 2 | R13: =IF(COUNT(H13:Q13)=10,SUM(H13:Q13),"") -> 25 | S13: =IF(ISNUMBER(R13),R13/30*100,"") -> 83.333333 | T13: =IF(COUNT(H13:J13,L13)=4,SUM(H13:J13,L13),"") -> 10 | U13: =IF(COUNT(K13,M13:O13)=4,SUM(K13,M13:O13),"") -> 11 | V13: =IF(COUNT(P13:Q13)=2,SUM(P13:Q13),"") -> 4 | W13: FY 2024-25 | AA13: 1 | AB13: 0 | AC13: unknown | AD13: 1 | AH13: =IF(AND(ISNUMBER(AG13),ISNUMBER(AF13),AF13>0),AG13/AF13,"") | AN13: ACC IR 2024-25 | AP13: per indicator - see Evidence_Log | AS13: OBS-012 | AT13: Workbook coded; single coder | AU13: 25 | AV13: Cement_Report.pdf | AW13: PDF p.13; section 7.2 | AX13: No | AY13: Yes | AZ13: Not supplied | BB13: =COUNT(H13:Q13) -> 10 | BC13: =IF(AND(ISNUMBER(R13),ISNUMBER(AU13)),R13-AU13,"") -> 0 | BV13: Reviewed supplied PDF/DOCX and related sources | BW13: Cement/Annexure A.xlsx | Cement/Annexure B.docx | Cement/Annexure C.xlsx | Cement/Annexure D.xlsx | Cement/Annexure E.xlsx | Cement/Cement_Report.pdf | BX13: CCTS_obligated, exchange, ownership, coder_id, second_coder_score, agreed_score, EU_export, revenue, total_assets, PAT, ROA, total_debt, finance_cost, cost_of_debt_proxy, capex, size_band, reporting_year, URL, date_accessed; No firm-level revenue/PAT/assets/debt/finance-cost table in supplied report or Word interviews. Survey and MDS values are respondent/perception data and cannot fill company financials. Single-coder identity and second coder are unrecorded. EU-specific exports not disclosed. Exact company-report URLs and access dates not supplied.
A14: JK Cement | B14: Cement | D14: 1 | G14: 1 | H14: 3 | I14: 3 | J14: 3 | K14: 3 | L14: 3 | M14: 3 | N14: 3 | O14: 3 | P14: 3 | Q14: 2 | R14: =IF(COUNT(H14:Q14)=10,SUM(H14:Q14),"") -> 29 | S14: =IF(ISNUMBER(R14),R14/30*100,"") -> 96.666667 | T14: =IF(COUNT(H14:J14,L14)=4,SUM(H14:J14,L14),"") -> 12 | U14: =IF(COUNT(K14,M14:O14)=4,SUM(K14,M14:O14),"") -> 12 | V14: =IF(COUNT(P14:Q14)=2,SUM(P14:Q14),"") -> 5 | W14: FY 2025-26 | AA14: 1 | AC14: unknown | AH14: =IF(AND(ISNUMBER(AG14),ISNUMBER(AF14),AF14>0),AG14/AF14,"") | AN14: JK Cement IR 2025-26 | AP14: per indicator - see Evidence_Log | AS14: OBS-013 | AT14: Workbook coded; single coder | AU14: 29 | AV14: Cement_Report.pdf | AW14: PDF p.13; section 7.2 | AX14: No | AY14: Yes | AZ14: Not supplied | BB14: =COUNT(H14:Q14) -> 10 | BC14: =IF(AND(ISNUMBER(R14),ISNUMBER(AU14)),R14-AU14,"") -> 0 | BO14: Negligible | BV14: Reviewed supplied PDF/DOCX and related sources | BW14: Cement/Annexure A.xlsx | Cement/Annexure B.docx | Cement/Annexure C.xlsx | Cement/Annexure D.xlsx | Cement/Annexure E.xlsx | Cement/Cement_Report.pdf | BX14: CCTS_obligated, exchange, ownership, coder_id, second_coder_score, agreed_score, export_intensity, EU_export, PAT_legacy_entity, revenue, total_assets, PAT, ROA, total_debt, finance_cost, cost_of_debt_proxy, capex, size_band, reporting_year, URL, date_accessed; No firm-level revenue/PAT/assets/debt/finance-cost table in supplied report or Word interviews. Survey and MDS values are respondent/perception data and cannot fill company financials. Single-coder identity and second coder are unrecorded. EU-specific exports not disclosed. Exact company-report URLs and access dates not supplied.
A15: UltraTech | B15: Cement | D15: 1 | G15: 1 | H15: 3 | I15: 3 | J15: 3 | K15: 3 | L15: 2 | M15: 2 | N15: 3 | O15: 3 | P15: 3 | Q15: 2 | R15: =IF(COUNT(H15:Q15)=10,SUM(H15:Q15),"") -> 27 | S15: =IF(ISNUMBER(R15),R15/30*100,"") -> 90 | T15: =IF(COUNT(H15:J15,L15)=4,SUM(H15:J15,L15),"") -> 11 | U15: =IF(COUNT(K15,M15:O15)=4,SUM(K15,M15:O15),"") -> 11 | V15: =IF(COUNT(P15:Q15)=2,SUM(P15:Q15),"") -> 5 | W15: FY 2025-26 | AA15: 1 | AB15: 0.0025 | AC15: unknown | AH15: =IF(AND(ISNUMBER(AG15),ISNUMBER(AF15),AF15>0),AG15/AF15,"") | AN15: UltraTech IR & Sustainability Report 2025-26 | AP15: per indicator - see Evidence_Log | AS15: OBS-014 | AT15: Workbook coded; single coder | AU15: 27 | AV15: Cement_Report.pdf | AW15: PDF p.13; section 7.2 | AX15: No | AY15: Yes | AZ15: Not supplied | BB15: =COUNT(H15:Q15) -> 10 | BC15: =IF(AND(ISNUMBER(R15),ISNUMBER(AU15)),R15-AU15,"") -> 0 | BH15: 49 | BV15: Reviewed supplied PDF/DOCX and related sources | BW15: Cement/Annexure A.xlsx | Cement/Annexure B.docx | Cement/Annexure C.xlsx | Cement/Annexure D.xlsx | Cement/Annexure E.xlsx | Cement/Cement_Report.pdf | BX15: CCTS_obligated, exchange, ownership, coder_id, second_coder_score, agreed_score, EU_export, PAT_legacy_entity, revenue, total_assets, PAT, ROA, total_debt, finance_cost, cost_of_debt_proxy, capex, size_band, reporting_year, URL, date_accessed; No firm-level revenue/PAT/assets/debt/finance-cost table in supplied report or Word interviews. Survey and MDS values are respondent/perception data and cannot fill company financials. Single-coder identity and second coder are unrecorded. EU-specific exports not disclosed. Exact company-report URLs and access dates not supplied.
A16: Ambuja Cements | B16: Cement | D16: 1 | G16: 1 | H16: 3 | I16: 1 | J16: 3 | K16: 3 | L16: 1 | M16: 2 | N16: 0 | O16: 3 | P16: 3 | Q16: 2 | R16: =IF(COUNT(H16:Q16)=10,SUM(H16:Q16),"") -> 21 | S16: =IF(ISNUMBER(R16),R16/30*100,"") -> 70 | T16: =IF(COUNT(H16:J16,L16)=4,SUM(H16:J16,L16),"") -> 8 | U16: =IF(COUNT(K16,M16:O16)=4,SUM(K16,M16:O16),"") -> 8 | V16: =IF(COUNT(P16:Q16)=2,SUM(P16:Q16),"") -> 5 | W16: FY 2024-25 | AA16: 1 | AB16: 0 | AC16: unknown | AD16: 1 | AH16: =IF(AND(ISNUMBER(AG16),ISNUMBER(AF16),AF16>0),AG16/AF16,"") | AN16: Ambuja IR 2024-25; Ambuja IR 2024-25 (reviewed) | AP16: per indicator - see Evidence_Log | AS16: OBS-015 | AT16: Workbook coded; single coder | AU16: 21 | AV16: Cement_Report.pdf | AW16: PDF p.13; section 7.2 | AX16: No | AY16: Yes | AZ16: Not supplied | BB16: =COUNT(H16:Q16) -> 10 | BC16: =IF(AND(ISNUMBER(R16),ISNUMBER(AU16)),R16-AU16,"") -> 0 | BV16: Reviewed supplied PDF/DOCX and related sources | BW16: Cement/Annexure A.xlsx | Cement/Annexure B.docx | Cement/Annexure C.xlsx | Cement/Annexure D.xlsx | Cement/Annexure E.xlsx | Cement/Cement_Report.pdf | BX16: CCTS_obligated, exchange, ownership, coder_id, second_coder_score, agreed_score, EU_export, revenue, total_assets, PAT, ROA, total_debt, finance_cost, cost_of_debt_proxy, capex, size_band, reporting_year, URL, date_accessed; No firm-level revenue/PAT/assets/debt/finance-cost table in supplied report or Word interviews. Survey and MDS values are respondent/perception data and cannot fill company financials. Single-coder identity and second coder are unrecorded. EU-specific exports not disclosed. Exact company-report URLs and access dates not supplied.
A17: JSW Cement | B17: Cement | D17: 1 | G17: 1 | H17: 3 | I17: 2 | J17: 3 | K17: 3 | L17: 1 | M17: 2 | N17: 0 | O17: 2 | P17: 3 | Q17: 2 | R17: =IF(COUNT(H17:Q17)=10,SUM(H17:Q17),"") -> 21 | S17: =IF(ISNUMBER(R17),R17/30*100,"") -> 70 | T17: =IF(COUNT(H17:J17,L17)=4,SUM(H17:J17,L17),"") -> 9 | U17: =IF(COUNT(K17,M17:O17)=4,SUM(K17,M17:O17),"") -> 7 | V17: =IF(COUNT(P17:Q17)=2,SUM(P17:Q17),"") -> 5 | W17: FY 2025-26 | AA17: 1 | AB17: 0 | AC17: unknown | AH17: =IF(AND(ISNUMBER(AG17),ISNUMBER(AF17),AF17>0),AG17/AF17,"") | AN17: JSW Cement IAR 2025-26; JSW Cement IAR 2025-26 (reviewed) | AP17: per indicator - see Evidence_Log | AS17: OBS-016 | AT17: Workbook coded; single coder | AU17: 21 | AV17: Cement_Report.pdf | AW17: PDF p.13; section 7.2 | AX17: No | AY17: Yes | AZ17: Not supplied | BB17: =COUNT(H17:Q17) -> 10 | BC17: =IF(AND(ISNUMBER(R17),ISNUMBER(AU17)),R17-AU17,"") -> 0 | BV17: Reviewed supplied PDF/DOCX and related sources | BW17: Cement/Annexure A.xlsx | Cement/Annexure B.docx | Cement/Annexure C.xlsx | Cement/Annexure D.xlsx | Cement/Annexure E.xlsx | Cement/Cement_Report.pdf | BX17: CCTS_obligated, exchange, ownership, coder_id, second_coder_score, agreed_score, EU_export, PAT_legacy_entity, revenue, total_assets, PAT, ROA, total_debt, finance_cost, cost_of_debt_proxy, capex, size_band, reporting_year, URL, date_accessed; No firm-level revenue/PAT/assets/debt/finance-cost table in supplied report or Word interviews. Survey and MDS values are respondent/perception data and cannot fill company financials. Single-coder identity and second coder are unrecorded. EU-specific exports not disclosed. Exact company-report URLs and access dates not supplied.
A18: Hindalco | B18: Aluminium | D18: 1 | F18: listed private | G18: 1 | H18: 3 | I18: 3 | J18: 3 | K18: 3 | L18: 3 | M18: 3 | N18: 3 | O18: 3 | P18: 3 | Q18: 3 | R18: =IF(COUNT(H18:Q18)=10,SUM(H18:Q18),"") -> 30 | S18: =IF(ISNUMBER(R18),R18/30*100,"") -> 100 | T18: =IF(COUNT(H18:J18,L18)=4,SUM(H18:J18,L18),"") -> 12 | U18: =IF(COUNT(K18,M18:O18)=4,SUM(K18,M18:O18),"") -> 12 | V18: =IF(COUNT(P18:Q18)=2,SUM(P18:Q18),"") -> 6 | W18: FY2024-25 | AA18: 1 | AE18: 238496 | AF18: 265991 | AG18: 16002 | AH18: =IF(AND(ISNUMBER(AG18),ISNUMBER(AF18),AF18>0),AG18/AF18,"") -> 0.06015993 | AK18: 0.0587 | AN18: Hindalco Integrated Annual Report 2024-25 incl. BRSR and assurance (report ref. 5) | AO18: FY2024-25 | AP18: not given in the sector report | PDF pp.14–15, Table 8 (DQS); PDF p.23, Table 14 (financials) | AS18: OBS-017 | AT18: Report matrix only; not independently verified | AU18: 30 | AV18: Aluminium_Report.pdf | AW18: PDF pp.14–15; Table 8 | AX18: No | AY18: No | AZ18: Inherited source values; verify scope/year | BB18: =COUNT(H18:Q18) -> 10 | BC18: =IF(AND(ISNUMBER(R18),ISNUMBER(AU18)),R18-AU18,"") -> 0 | BD18: Report scores transcribed as stated; underlying primary disclosure and indicator anchors need verification. | BU18: Primary | BV18: Reviewed supplied PDF/DOCX and related sources | BW18: Aluminium Group/Aluminium_Report.pdf (all pages) | Aluminium Group/Compiled_Interview_Transcripts.docx (all paragraphs and table) | Aluminium Group/Call_logs.xlsx (Call logs sheet; contact values not copied) | BX18: CCTS_obligated, exchange, coder_id, second_coder_score, agreed_score, export_intensity, EU_export, PAT_legacy_entity, total_debt, finance_cost, capex, size_band, URL, date_accessed; No exchange name, exact export/EU-export share, PAT legacy status, finance-cost numerator, debt balance, total capex, coder identity or access date supplied. Table 14 reports the already-transcribed financial values but does not supply debt, finance cost or capex inputs. The interview firms differ from the ten listed disclosure-panel names, so their loan/export claims cannot populate these rows. Firm-level CCTS obligation needs legal/unit evidence not present.
A19: Vedanta | B19: Aluminium | D19: 1 | F19: listed private | G19: 1 | H19: 3 | I19: 3 | J19: 3 | K19: 3 | L19: 3 | M19: 3 | N19: 3 | O19: 3 | P19: 3 | Q19: 3 | R19: =IF(COUNT(H19:Q19)=10,SUM(H19:Q19),"") -> 30 | S19: =IF(ISNUMBER(R19),R19/30*100,"") -> 100 | T19: =IF(COUNT(H19:J19,L19)=4,SUM(H19:J19,L19),"") -> 12 | U19: =IF(COUNT(K19,M19:O19)=4,SUM(K19,M19:O19),"") -> 12 | V19: =IF(COUNT(P19:Q19)=2,SUM(P19:Q19),"") -> 6 | W19: FY2024-25 | AA19: 1 | AH19: =IF(AND(ISNUMBER(AG19),ISNUMBER(AF19),AF19>0),AG19/AF19,"") | AN19: Vedanta Integrated Report and Annual Accounts FY2024-25; Climate Action Report 2025 (ref. 14) | AP19: not given in the sector report | PDF pp.14–15, Table 8 (DQS); PDF p.23, Table 14 (financial data availability) | AQ19: https://www.vedantalimited.com/eng/esg-reporting.php | AS19: OBS-018 | AT19: Report matrix only; not independently verified | AU19: 30 | AV19: Aluminium_Report.pdf | AW19: PDF pp.14–15; Table 8 | AX19: No | AY19: No | AZ19: Not supplied | BB19: =COUNT(H19:Q19) -> 10 | BC19: =IF(AND(ISNUMBER(R19),ISNUMBER(AU19)),R19-AU19,"") -> 0 | BD19: Report scores transcribed as stated; underlying primary disclosure and indicator anchors need verification. | BU19: Primary | BV19: Reviewed supplied PDF/DOCX and related sources | BW19: Aluminium Group/Aluminium_Report.pdf (all pages) | Aluminium Group/Compiled_Interview_Transcripts.docx (all paragraphs and table) | Aluminium Group/Call_logs.xlsx (Call logs sheet; contact values not copied) | BX19: CCTS_obligated, exchange, coder_id, second_coder_score, agreed_score, export_intensity, EU_export, PAT_legacy_entity, revenue, total_assets, PAT, ROA, total_debt, finance_cost, cost_of_debt_proxy, capex, size_band, reporting_year, date_accessed; No exchange name, exact export/EU-export share, PAT legacy status, finance-cost numerator, debt balance, total capex, coder identity or access date supplied. Table 14 explicitly says no financial document sourced for this firm; no financial values can be filled from these documents. The interview firms differ from the ten listed disclosure-panel names, so their loan/export claims cannot populate these rows. Firm-level CCTS obligation needs legal/unit evidence not present.
A20: NALCO | B20: Aluminium | D20: 1 | F20: PSU | G20: 1 | H20: 3 | I20: 3 | J20: 3 | K20: 3 | L20: 3 | M20: 3 | N20: 3 | O20: 3 | P20: 3 | Q20: 3 | R20: =IF(COUNT(H20:Q20)=10,SUM(H20:Q20),"") -> 30 | S20: =IF(ISNUMBER(R20),R20/30*100,"") -> 100 | T20: =IF(COUNT(H20:J20,L20)=4,SUM(H20:J20,L20),"") -> 12 | U20: =IF(COUNT(K20,M20:O20)=4,SUM(K20,M20:O20),"") -> 12 | V20: =IF(COUNT(P20:Q20)=2,SUM(P20:Q20),"") -> 6 | W20: FY2024-25 | AA20: 1 | AE20: 16662.21 | AF20: 22882 | AG20: 5324.67 | AH20: =IF(AND(ISNUMBER(AG20),ISNUMBER(AF20),AF20>0),AG20/AF20,"") -> 0.23270125 | AN20: NALCO 44th Annual Report 2024-25 incl. BRSR (ref. 9) | AO20: FY2024-25 | AP20: not given in the sector report | PDF pp.14–15, Table 8 (DQS); PDF p.23, Table 14 (financials) | AS20: OBS-019 | AT20: Report matrix only; not independently verified | AU20: 30 | AV20: Aluminium_Report.pdf | AW20: PDF pp.14–15; Table 8 | AX20: No | AY20: No | AZ20: Inherited source values; verify scope/year | BB20: =COUNT(H20:Q20) -> 10 | BC20: =IF(AND(ISNUMBER(R20),ISNUMBER(AU20)),R20-AU20,"") -> 0 | BD20: Report scores transcribed as stated; underlying primary disclosure and indicator anchors need verification. | BU20: Primary | BV20: Reviewed supplied PDF/DOCX and related sources | BW20: Aluminium Group/Aluminium_Report.pdf (all pages) | Aluminium Group/Compiled_Interview_Transcripts.docx (all paragraphs and table) | Aluminium Group/Call_logs.xlsx (Call logs sheet; contact values not copied) | BX20: CCTS_obligated, exchange, coder_id, second_coder_score, agreed_score, export_intensity, EU_export, PAT_legacy_entity, total_debt, finance_cost, cost_of_debt_proxy, capex, size_band, URL, date_accessed; No exchange name, exact export/EU-export share, PAT legacy status, finance-cost numerator, debt balance, total capex, coder identity or access date supplied. Cost-of-debt proxy is N/M because of no material borrowing, not a numeric zero. Total assets ~₹22,882 crore are approximate. The interview firms differ from the ten listed disclosure-panel names, so their loan/export claims cannot populate these rows. Firm-level CCTS obligation needs legal/unit evidence not present.
A21: BALCO | B21: Aluminium | F21: Vedanta Group majority-owned | H21: 3 | I21: 0 | J21: 0 | K21: 2 | L21: 2 | M21: 1 | N21: 3 | O21: 3 | P21: 3 | Q21: 0 | R21: =IF(COUNT(H21:Q21)=10,SUM(H21:Q21),"") -> 17 | S21: =IF(ISNUMBER(R21),R21/30*100,"") -> 56.666667 | T21: =IF(COUNT(H21:J21,L21)=4,SUM(H21:J21,L21),"") -> 5 | U21: =IF(COUNT(K21,M21:O21)=4,SUM(K21,M21:O21),"") -> 9 | V21: =IF(COUNT(P21:Q21)=2,SUM(P21:Q21),"") -> 3 | W21: FY2024-25 | AA21: 1 | AH21: =IF(AND(ISNUMBER(AG21),ISNUMBER(AF21),AF21>0),AG21/AF21,"") | AN21: BALCO Integrated Annual Report and sustainability pages | AP21: not given in the sector report | PDF pp.14–15, Table 8 (DQS); PDF p.23, Table 14 (financial data availability) | AS21: OBS-020 | AT21: Report matrix only; not independently verified | AU21: 17 | AV21: Aluminium_Report.pdf | AW21: PDF pp.14–15; Table 8 | AX21: No | AY21: No | AZ21: Not supplied | BB21: =COUNT(H21:Q21) -> 10 | BC21: =IF(AND(ISNUMBER(R21),ISNUMBER(AU21)),R21-AU21,"") -> 0 | BD21: Report scores transcribed as stated; underlying primary disclosure and indicator anchors need verification. | BU21: Primary | BV21: Reviewed supplied PDF/DOCX and related sources | BW21: Aluminium Group/Aluminium_Report.pdf (all pages) | Aluminium Group/Compiled_Interview_Transcripts.docx (all paragraphs and table) | Aluminium Group/Call_logs.xlsx (Call logs sheet; contact values not copied) | BX21: CCTS_obligated, listed, exchange, BRSR_filer, coder_id, second_coder_score, agreed_score, export_intensity, EU_export, PAT_legacy_entity, revenue, total_assets, PAT, ROA, total_debt, finance_cost, cost_of_debt_proxy, capex, size_band, reporting_year, URL, date_accessed; No exchange name, exact export/EU-export share, PAT legacy status, finance-cost numerator, debt balance, total capex, coder identity or access date supplied. Table 14 explicitly says no financial document sourced for this firm; no financial values can be filled from these documents. The interview firms differ from the ten listed disclosure-panel names, so their loan/export claims cannot populate these rows. Firm-level CCTS obligation needs legal/unit evidence not present.
A22: Maan Aluminium | B22: Aluminium | D22: 1 | H22: 3 | I22: 0 | J22: 0 | K22: 0 | L22: 0 | M22: 0 | N22: 3 | O22: 2 | P22: 2 | Q22: 0 | R22: =IF(COUNT(H22:Q22)=10,SUM(H22:Q22),"") -> 10 | S22: =IF(ISNUMBER(R22),R22/30*100,"") -> 33.333333 | T22: =IF(COUNT(H22:J22,L22)=4,SUM(H22:J22,L22),"") -> 3 | U22: =IF(COUNT(K22,M22:O22)=4,SUM(K22,M22:O22),"") -> 5 | V22: =IF(COUNT(P22:Q22)=2,SUM(P22:Q22),"") -> 2 | W22: FY2024-25 | AE22: 810.17 | AF22: 299.63 | AG22: 15.51 | AH22: =IF(AND(ISNUMBER(AG22),ISNUMBER(AF22),AF22>0),AG22/AF22,"") -> 0.051763842 | AK22: 0.0536 | AN22: Aluminium sector report, Table 8 | AO22: FY2024-25 | AP22: not given in the sector report | PDF pp.14–15, Table 8 (DQS); PDF p.23, Table 14 (financials) | AS22: OBS-021 | AT22: Report matrix only; not independently verified | AU22: 10 | AV22: Aluminium_Report.pdf | AW22: PDF pp.14–15; Table 8 | AX22: No | AY22: No | AZ22: Inherited source values; verify scope/year | BB22: =COUNT(H22:Q22) -> 10 | BC22: =IF(AND(ISNUMBER(R22),ISNUMBER(AU22)),R22-AU22,"") -> 0 | BD22: Report scores transcribed as stated; underlying primary disclosure and indicator anchors need verification. | BU22: Downstream/Secondary | BV22: Reviewed supplied PDF/DOCX and related sources | BW22: Aluminium Group/Aluminium_Report.pdf (all pages) | Aluminium Group/Compiled_Interview_Transcripts.docx (all paragraphs and table) | Aluminium Group/Call_logs.xlsx (Call logs sheet; contact values not copied) | BX22: CCTS_obligated, exchange, ownership, BRSR_filer, coder_id, second_coder_score, agreed_score, CBAM_covered_product, export_intensity, EU_export, PAT_legacy_entity, total_debt, finance_cost, capex, size_band, URL, date_accessed; No exchange name, exact export/EU-export share, PAT legacy status, finance-cost numerator, debt balance, total capex, coder identity or access date supplied. Table 14 reports the already-transcribed financial values but does not supply debt, finance cost or capex inputs. The interview firms differ from the ten listed disclosure-panel names, so their loan/export claims cannot populate these rows. Firm-level CCTS obligation needs legal/unit evidence not present.
A23: Century Extrusions | B23: Aluminium | D23: 1 | H23: 3 | I23: 0 | J23: 0 | K23: 0 | L23: 0 | M23: 0 | N23: 2 | O23: 2 | P23: 2 | Q23: 0 | R23: =IF(COUNT(H23:Q23)=10,SUM(H23:Q23),"") -> 9 | S23: =IF(ISNUMBER(R23),R23/30*100,"") -> 30 | T23: =IF(COUNT(H23:J23,L23)=4,SUM(H23:J23,L23),"") -> 3 | U23: =IF(COUNT(K23,M23:O23)=4,SUM(K23,M23:O23),"") -> 4 | V23: =IF(COUNT(P23:Q23)=2,SUM(P23:Q23),"") -> 2 | W23: FY2024-25 | AE23: 479.3 | AG23: 10.97 | AH23: =IF(AND(ISNUMBER(AG23),ISNUMBER(AF23),AF23>0),AG23/AF23,"") | AN23: Aluminium sector report, Table 8 | AO23: FY2025-26 | AP23: not given in the sector report | PDF pp.14–15, Table 8 (DQS); PDF p.23, Table 14 (financials) | AS23: OBS-022 | AT23: Report matrix only; not independently verified | AU23: 9 | AV23: Aluminium_Report.pdf | AW23: PDF pp.14–15; Table 8 | AX23: No | AY23: No | AZ23: Inherited source values; verify scope/year | BB23: =COUNT(H23:Q23) -> 10 | BC23: =IF(AND(ISNUMBER(R23),ISNUMBER(AU23)),R23-AU23,"") -> 0 | BD23: Report scores transcribed as stated; underlying primary disclosure and indicator anchors need verification. | BU23: Downstream/Secondary | BV23: Reviewed supplied PDF/DOCX and related sources | BW23: Aluminium Group/Aluminium_Report.pdf (all pages) | Aluminium Group/Compiled_Interview_Transcripts.docx (all paragraphs and table) | Aluminium Group/Call_logs.xlsx (Call logs sheet; contact values not copied) | BX23: CCTS_obligated, exchange, ownership, BRSR_filer, coder_id, second_coder_score, agreed_score, CBAM_covered_product, export_intensity, EU_export, PAT_legacy_entity, total_assets, ROA, total_debt, finance_cost, cost_of_debt_proxy, capex, size_band, URL, date_accessed; No exchange name, exact export/EU-export share, PAT legacy status, finance-cost numerator, debt balance, total capex, coder identity or access date supplied. Financial context is FY2025-26, whereas DQS is FY2024-25; assets/ROA/debt proxy are N/A and cannot be reconstructed. The interview firms differ from the ten listed disclosure-panel names, so their loan/export claims cannot populate these rows. Firm-level CCTS obligation needs legal/unit evidence not present.
A24: PG Foils | B24: Aluminium | D24: 1 | H24: 3 | I24: 0 | J24: 0 | K24: 0 | L24: 0 | M24: 0 | N24: 2 | O24: 2 | P24: 2 | Q24: 0 | R24: =IF(COUNT(H24:Q24)=10,SUM(H24:Q24),"") -> 9 | S24: =IF(ISNUMBER(R24),R24/30*100,"") -> 30 | T24: =IF(COUNT(H24:J24,L24)=4,SUM(H24:J24,L24),"") -> 3 | U24: =IF(COUNT(K24,M24:O24)=4,SUM(K24,M24:O24),"") -> 4 | V24: =IF(COUNT(P24:Q24)=2,SUM(P24:Q24),"") -> 2 | W24: FY2024-25 | AE24: 491.4 | AF24: 423.81 | AG24: 31.66 | AH24: =IF(AND(ISNUMBER(AG24),ISNUMBER(AF24),AF24>0),AG24/AF24,"") -> 0.074703287 | AN24: PG Foils annual report and corporate disclosures FY2024-25 (ref. 11) | AO24: FY2024-25 | AP24: not given in the sector report | PDF pp.14–15, Table 8 (DQS); PDF p.23, Table 14 (financials) | AS24: OBS-023 | AT24: Report matrix only; not independently verified | AU24: 9 | AV24: Aluminium_Report.pdf | AW24: PDF pp.14–15; Table 8 | AX24: No | AY24: No | AZ24: Inherited source values; verify scope/year | BB24: =COUNT(H24:Q24) -> 10 | BC24: =IF(AND(ISNUMBER(R24),ISNUMBER(AU24)),R24-AU24,"") -> 0 | BD24: Report scores transcribed as stated; underlying primary disclosure and indicator anchors need verification. | BU24: Downstream/Secondary | BV24: Reviewed supplied PDF/DOCX and related sources | BW24: Aluminium Group/Aluminium_Report.pdf (all pages) | Aluminium Group/Compiled_Interview_Transcripts.docx (all paragraphs and table) | Aluminium Group/Call_logs.xlsx (Call logs sheet; contact values not copied) | BX24: CCTS_obligated, exchange, ownership, BRSR_filer, coder_id, second_coder_score, agreed_score, CBAM_covered_product, export_intensity, EU_export, PAT_legacy_entity, total_debt, finance_cost, cost_of_debt_proxy, capex, size_band, URL, date_accessed; No exchange name, exact export/EU-export share, PAT legacy status, finance-cost numerator, debt balance, total capex, coder identity or access date supplied. Table 14 reports the already-transcribed financial values but does not supply debt, finance cost or capex inputs. The interview firms differ from the ten listed disclosure-panel names, so their loan/export claims cannot populate these rows. Firm-level CCTS obligation needs legal/unit evidence not present.
A25: Manaksia Aluminium | B25: Aluminium | D25: 1 | H25: 3 | I25: 0 | J25: 0 | K25: 0 | L25: 0 | M25: 0 | N25: 2 | O25: 1 | P25: 2 | Q25: 0 | R25: =IF(COUNT(H25:Q25)=10,SUM(H25:Q25),"") -> 8 | S25: =IF(ISNUMBER(R25),R25/30*100,"") -> 26.666667 | T25: =IF(COUNT(H25:J25,L25)=4,SUM(H25:J25,L25),"") -> 3 | U25: =IF(COUNT(K25,M25:O25)=4,SUM(K25,M25:O25),"") -> 3 | V25: =IF(COUNT(P25:Q25)=2,SUM(P25:Q25),"") -> 2 | W25: FY2024-25 | AE25: 509.15 | AF25: 504.26 | AG25: 6.05 | AH25: =IF(AND(ISNUMBER(AG25),ISNUMBER(AF25),AF25>0),AG25/AF25,"") -> 0.011997779 | AK25: 0.1339 | AN25: Aluminium sector report, Table 8 | AO25: FY2024-25 | AP25: not given in the sector report | PDF pp.14–15, Table 8 (DQS); PDF p.23, Table 14 (financials) | AS25: OBS-024 | AT25: Report matrix only; not independently verified | AU25: 8 | AV25: Aluminium_Report.pdf | AW25: PDF pp.14–15; Table 8 | AX25: No | AY25: No | AZ25: Inherited source values; verify scope/year | BB25: =COUNT(H25:Q25) -> 10 | BC25: =IF(AND(ISNUMBER(R25),ISNUMBER(AU25)),R25-AU25,"") -> 0 | BD25: Report scores transcribed as stated; underlying primary disclosure and indicator anchors need verification. | BU25: Downstream/Secondary | BV25: Reviewed supplied PDF/DOCX and related sources | BW25: Aluminium Group/Aluminium_Report.pdf (all pages) | Aluminium Group/Compiled_Interview_Transcripts.docx (all paragraphs and table) | Aluminium Group/Call_logs.xlsx (Call logs sheet; contact values not copied) | BX25: CCTS_obligated, exchange, ownership, BRSR_filer, coder_id, second_coder_score, agreed_score, CBAM_covered_product, export_intensity, EU_export, PAT_legacy_entity, total_debt, finance_cost, capex, size_band, URL, date_accessed; No exchange name, exact export/EU-export share, PAT legacy status, finance-cost numerator, debt balance, total capex, coder identity or access date supplied. Table 14 reports the already-transcribed financial values but does not supply debt, finance cost or capex inputs. The interview firms differ from the ten listed disclosure-panel names, so their loan/export claims cannot populate these rows. Firm-level CCTS obligation needs legal/unit evidence not present.
A26: Alufluoride | B26: Aluminium | D26: 1 | H26: 3 | I26: 0 | J26: 0 | K26: 0 | L26: 0 | M26: 0 | N26: 2 | O26: 1 | P26: 2 | Q26: 0 | R26: =IF(COUNT(H26:Q26)=10,SUM(H26:Q26),"") -> 8 | S26: =IF(ISNUMBER(R26),R26/30*100,"") -> 26.666667 | T26: =IF(COUNT(H26:J26,L26)=4,SUM(H26:J26,L26),"") -> 3 | U26: =IF(COUNT(K26,M26:O26)=4,SUM(K26,M26:O26),"") -> 3 | V26: =IF(COUNT(P26:Q26)=2,SUM(P26:Q26),"") -> 2 | W26: FY2024-25 | AE26: 188.52 | AF26: 149.23 | AG26: 18.09 | AH26: =IF(AND(ISNUMBER(AG26),ISNUMBER(AF26),AF26>0),AG26/AF26,"") -> 0.12122227 | AK26: 0.1264 | AN26: Aluminium sector report, Table 8 | AO26: FY2024-25 | AP26: not given in the sector report | PDF pp.14–15, Table 8 (DQS); PDF p.23, Table 14 (financials) | AS26: OBS-025 | AT26: Report matrix only; not independently verified | AU26: 8 | AV26: Aluminium_Report.pdf | AW26: PDF pp.14–15; Table 8 | AX26: No | AY26: No | AZ26: Inherited source values; verify scope/year | BB26: =COUNT(H26:Q26) -> 10 | BC26: =IF(AND(ISNUMBER(R26),ISNUMBER(AU26)),R26-AU26,"") -> 0 | BD26: Report scores transcribed as stated; underlying primary disclosure and indicator anchors need verification. | BU26: Downstream/Secondary | BV26: Reviewed supplied PDF/DOCX and related sources | BW26: Aluminium Group/Aluminium_Report.pdf (all pages) | Aluminium Group/Compiled_Interview_Transcripts.docx (all paragraphs and table) | Aluminium Group/Call_logs.xlsx (Call logs sheet; contact values not copied) | BX26: CCTS_obligated, exchange, ownership, BRSR_filer, coder_id, second_coder_score, agreed_score, CBAM_covered_product, export_intensity, EU_export, PAT_legacy_entity, total_debt, finance_cost, capex, size_band, URL, date_accessed; No exchange name, exact export/EU-export share, PAT legacy status, finance-cost numerator, debt balance, total capex, coder identity or access date supplied. Table 14 reports the already-transcribed financial values but does not supply debt, finance cost or capex inputs. The interview firms differ from the ten listed disclosure-panel names, so their loan/export claims cannot populate these rows. Firm-level CCTS obligation needs legal/unit evidence not present.
A27: Euro Panel Products | B27: Aluminium | D27: 1 | H27: 3 | I27: 0 | J27: 0 | K27: 0 | L27: 0 | M27: 0 | N27: 1 | O27: 1 | P27: 2 | Q27: 0 | R27: =IF(COUNT(H27:Q27)=10,SUM(H27:Q27),"") -> 7 | S27: =IF(ISNUMBER(R27),R27/30*100,"") -> 23.333333 | T27: =IF(COUNT(H27:J27,L27)=4,SUM(H27:J27,L27),"") -> 3 | U27: =IF(COUNT(K27,M27:O27)=4,SUM(K27,M27:O27),"") -> 2 | V27: =IF(COUNT(P27:Q27)=2,SUM(P27:Q27),"") -> 2 | W27: FY2024-25 | AH27: =IF(AND(ISNUMBER(AG27),ISNUMBER(AF27),AF27>0),AG27/AF27,"") | AN27: Aluminium sector report, Table 8 | AP27: not given in the sector report | PDF pp.14–15, Table 8 (DQS); PDF p.23, Table 14 (financial data availability) | AS27: OBS-026 | AT27: Report matrix only; not independently verified | AU27: 7 | AV27: Aluminium_Report.pdf | AW27: PDF pp.14–15; Table 8 | AX27: No | AY27: No | AZ27: Not supplied | BB27: =COUNT(H27:Q27) -> 10 | BC27: =IF(AND(ISNUMBER(R27),ISNUMBER(AU27)),R27-AU27,"") -> 0 | BD27: Report scores transcribed as stated; underlying primary disclosure and indicator anchors need verification. | BU27: Downstream/Secondary | BV27: Reviewed supplied PDF/DOCX and related sources | BW27: Aluminium Group/Aluminium_Report.pdf (all pages) | Aluminium Group/Compiled_Interview_Transcripts.docx (all paragraphs and table) | Aluminium Group/Call_logs.xlsx (Call logs sheet; contact values not copied) | BX27: CCTS_obligated, exchange, ownership, BRSR_filer, coder_id, second_coder_score, agreed_score, CBAM_covered_product, export_intensity, EU_export, PAT_legacy_entity, revenue, total_assets, PAT, ROA, total_debt, finance_cost, cost_of_debt_proxy, capex, size_band, reporting_year, URL, date_accessed; No exchange name, exact export/EU-export share, PAT legacy status, finance-cost numerator, debt balance, total capex, coder identity or access date supplied. Table 14 explicitly says no financial document sourced for this firm; no financial values can be filled from these documents. The interview firms differ from the ten listed disclosure-panel names, so their loan/export claims cannot populate these rows. Firm-level CCTS obligation needs legal/unit evidence not present.
A28: IFFCO | B28: Fertilisers & chemicals | D28: 0 | F28: cooperative | G28: 0 | R28: =IF(COUNT(H28:Q28)=10,SUM(H28:Q28),"") | S28: =IF(ISNUMBER(R28),R28/30*100,"") | T28: =IF(COUNT(H28:J28,L28)=4,SUM(H28:J28,L28),"") | U28: =IF(COUNT(K28,M28:O28)=4,SUM(K28,M28:O28),"") | V28: =IF(COUNT(P28:Q28)=2,SUM(P28:Q28),"") | W28: FY2025-26 | X28: Research coder | AC28: unknown | AH28: =IF(AND(ISNUMBER(AG28),ISNUMBER(AF28),AF28>0),AG28/AF28,"") | AM28: Large | AN28: IFFCO Annual Report / public disclosures | AP28: per indicator - see Evidence_Log | AQ28: IFFCO official annual-report portal | AS28: OBS-027 | AT28: Out of scope (BRSR); no zero assigned | AV28: Fertilisers_and_Chemicals_Report.pdf | AW28: PDF pp.18–20; Tables 15–16 | AX28: No | AY28: No | AZ28: Not supplied | BB28: =COUNT(H28:Q28) -> 0 | BC28: =IF(AND(ISNUMBER(R28),ISNUMBER(AU28)),R28-AU28,"") | BF28: 1 | BG28: Directly covered or expected to have direct compliance obligations | BI28: 0 | BK28: No BRSR (not SEBI-listed) | BO28: <10% | BT28: 5–15%; 15–30% | BV28: Reviewed supplied PDF/DOCX and related sources | BW28: Fertilisers_and_Chemicals_Report.pdf | Fertilisers_and_Chemicals_Report.docx | Supporting material/Primary Interview Transcripts.docx | Supporting material/Shared Survey Form.pdf | Supporting material/Disclosure_Coding_Sheet.xlsx | Supporting material/Survey_Responses.xlsx | Supporting material/Respondent_Log.xlsx | BX28: CCTS_obligated, exchange, I1, I2, I3, I4, I5, I6, I7, I8, I9, I10, DQS_total, DQS_100, sub_quantification, sub_strategy, sub_credibility, second_coder_score, agreed_score, CBAM_covered_product, export_intensity, EU_export, PAT_legacy_entity, revenue, total_assets, PAT, ROA, total_debt, finance_cost, cost_of_debt_proxy, capex, reporting_year, date_accessed; No exact export ratio/EU destination, exchange, final unit-level CCTS obligation, PAT legacy status, comparable total capex, finance costs or second-coder values are provided. DQS is out of scope, not zero; report states public financials not found.
A29: DCM Shriram | B29: Fertilisers & chemicals | D29: 1 | F29: listed private | H29: 3 | I29: 3 | J29: 2 | K29: 3 | L29: 2 | M29: 2 | N29: 0 | O29: 2 | P29: 2 | Q29: 2 | R29: =IF(COUNT(H29:Q29)=10,SUM(H29:Q29),"") -> 21 | S29: =IF(ISNUMBER(R29),R29/30*100,"") -> 70 | T29: =IF(COUNT(H29:J29,L29)=4,SUM(H29:J29,L29),"") -> 10 | U29: =IF(COUNT(K29,M29:O29)=4,SUM(K29,M29:O29),"") -> 7 | V29: =IF(COUNT(P29:Q29)=2,SUM(P29:Q29),"") -> 4 | W29: FY2024-25 | X29: Research coder | AC29: unknown | AE29: 13538 | AH29: =IF(AND(ISNUMBER(AG29),ISNUMBER(AF29),AF29>0),AG29/AF29,"") | AM29: Large | AN29: FY2024-25 Annual Report + Sustainability Report | AO29: FY2025-26 | AP29: per indicator - see Evidence_Log | AQ29: Public company filing / annual-report source | AS29: OBS-028 | AT29: CONFLICT: workbook vs report — review | AV29: Fertilisers_and_Chemicals_Report.pdf | AW29: PDF pp.18–20; Tables 15–16 | AX29: Yes | AY29: No | AZ29: Report financials transcribed; ₹856cr is adjusted for a one-time ₹239cr deferred-tax credit, not unqualified PAT. ₹1,767cr is NET debt, not total debt. | BB29: =COUNT(H29:Q29) -> 10 | BC29: =IF(AND(ISNUMBER(R29),ISNUMBER(AU29)),R29-AU29,"") | BD29: Resolve report/workbook version and sample mismatch before analysis. | BF29: 1 | BG29: Directly covered or expected to have direct compliance obligations | BI29: 2 | BJ29: 856 | BK29: Limited (Deloitte) | BO29: 10–30% | BR29: 1767 | BT29: 5–15% | BV29: Reviewed supplied PDF/DOCX and related sources | BW29: Fertilisers_and_Chemicals_Report.pdf | Fertilisers_and_Chemicals_Report.docx | Supporting material/Primary Interview Transcripts.docx | Supporting material/Shared Survey Form.pdf | Supporting material/Disclosure_Coding_Sheet.xlsx | Supporting material/Survey_Responses.xlsx | Supporting material/Respondent_Log.xlsx | BX29: CCTS_obligated, exchange, BRSR_filer, second_coder_score, agreed_score, CBAM_covered_product, export_intensity, EU_export, PAT_legacy_entity, total_assets, PAT, ROA, total_debt, finance_cost, cost_of_debt_proxy, capex, date_accessed; No exact export ratio/EU destination, exchange, final unit-level CCTS obligation, PAT legacy status, comparable total capex, finance costs or second-coder values are provided.
